2020-11-03 22:26:10.255 INFO _internal - _log:  * Running on http://0.0.0.0:5000/ (Press CTRL+C to quit)
2020-11-03 22:26:12.725 ERROR app - log_exception: Exception on /respuestas [GET]
Traceback (most recent call last):
  File "C:\Python\lib\site-packages\flask\app.py", line 2446, in wsgi_app
    response = self.full_dispatch_request()
  File "C:\Python\lib\site-packages\flask\app.py", line 1951, in full_dispatch_request
    rv = self.handle_user_exception(e)
  File "C:\Python\lib\site-packages\flask\app.py", line 1820, in handle_user_exception
    reraise(exc_type, exc_value, tb)
  File "C:\Python\lib\site-packages\flask\_compat.py", line 39, in reraise
    raise value
  File "C:\Python\lib\site-packages\flask\app.py", line 1949, in full_dispatch_request
    rv = self.dispatch_request()
  File "C:\Python\lib\site-packages\flask\app.py", line 1935, in dispatch_request
    return self.view_functions[rule.endpoint](**req.view_args)
  File "api.py", line 60, in respuestas
    return jsonify(result),200
  File "C:\Python\lib\site-packages\flask\json\__init__.py", line 370, in jsonify
    dumps(data, indent=indent, separators=separators) + "\n",
  File "C:\Python\lib\site-packages\flask\json\__init__.py", line 211, in dumps
    rv = _json.dumps(obj, **kwargs)
  File "C:\Python\lib\json\__init__.py", line 234, in dumps
    return cls(
  File "C:\Python\lib\json\encoder.py", line 199, in encode
    chunks = self.iterencode(o, _one_shot=True)
  File "C:\Python\lib\json\encoder.py", line 257, in iterencode
    return _iterencode(o, 0)
  File "C:\Python\lib\site-packages\flask\json\__init__.py", line 100, in default
    return _json.JSONEncoder.default(self, o)
  File "C:\Python\lib\json\encoder.py", line 179, in default
    raise TypeError(f'Object of type {o.__class__.__name__} '
TypeError: Object of type Row is not JSON serializable
2020-11-03 22:26:12.764 INFO _internal - _log: 127.0.0.1 - - [03/Nov/2020 22:26:12] "[35m[1mGET /respuestas HTTP/1.1[0m" 500 -
2020-11-03 22:27:09.104 INFO _internal - _log:  * Running on http://0.0.0.0:5000/ (Press CTRL+C to quit)
2020-11-03 22:27:12.087 ERROR app - log_exception: Exception on /respuestas [GET]
Traceback (most recent call last):
  File "C:\Python\lib\site-packages\flask\app.py", line 2446, in wsgi_app
    response = self.full_dispatch_request()
  File "C:\Python\lib\site-packages\flask\app.py", line 1951, in full_dispatch_request
    rv = self.handle_user_exception(e)
  File "C:\Python\lib\site-packages\flask\app.py", line 1820, in handle_user_exception
    reraise(exc_type, exc_value, tb)
  File "C:\Python\lib\site-packages\flask\_compat.py", line 39, in reraise
    raise value
  File "C:\Python\lib\site-packages\flask\app.py", line 1949, in full_dispatch_request
    rv = self.dispatch_request()
  File "C:\Python\lib\site-packages\flask\app.py", line 1935, in dispatch_request
    return self.view_functions[rule.endpoint](**req.view_args)
  File "api.py", line 64, in respuestas
    return jsonify(resp),200
  File "C:\Python\lib\site-packages\flask\json\__init__.py", line 370, in jsonify
    dumps(data, indent=indent, separators=separators) + "\n",
  File "C:\Python\lib\site-packages\flask\json\__init__.py", line 211, in dumps
    rv = _json.dumps(obj, **kwargs)
  File "C:\Python\lib\json\__init__.py", line 234, in dumps
    return cls(
  File "C:\Python\lib\json\encoder.py", line 199, in encode
    chunks = self.iterencode(o, _one_shot=True)
  File "C:\Python\lib\json\encoder.py", line 257, in iterencode
    return _iterencode(o, 0)
  File "C:\Python\lib\site-packages\flask\json\__init__.py", line 100, in default
    return _json.JSONEncoder.default(self, o)
  File "C:\Python\lib\json\encoder.py", line 179, in default
    raise TypeError(f'Object of type {o.__class__.__name__} '
TypeError: Object of type Row is not JSON serializable
2020-11-03 22:27:12.091 INFO _internal - _log: 127.0.0.1 - - [03/Nov/2020 22:27:12] "[35m[1mGET /respuestas HTTP/1.1[0m" 500 -
2020-11-03 22:27:44.015 INFO _internal - _log:  * Running on http://0.0.0.0:5000/ (Press CTRL+C to quit)
2020-11-03 22:27:45.644 INFO _internal - _log: 127.0.0.1 - - [03/Nov/2020 22:27:45] "[37mGET /respuestas HTTP/1.1[0m" 200 -
2020-11-03 22:28:38.626 INFO _internal - _log:  * Running on http://0.0.0.0:5000/ (Press CTRL+C to quit)
2020-11-03 22:28:53.007 INFO _internal - _log: 127.0.0.1 - - [03/Nov/2020 22:28:53] "[37mGET /respuestas HTTP/1.1[0m" 200 -
2020-11-03 22:29:47.020 INFO _internal - _log:  * Running on http://0.0.0.0:5000/ (Press CTRL+C to quit)
2020-11-03 22:29:50.966 INFO _internal - _log: 127.0.0.1 - - [03/Nov/2020 22:29:50] "[37mGET /respuestas HTTP/1.1[0m" 200 -
2020-11-03 22:44:25.266 INFO _internal - _log: 127.0.0.1 - - [03/Nov/2020 22:44:25] "[31m[1mPOST /respuestas HTTP/1.0[0m" 405 -
2020-11-03 22:44:41.577 INFO _internal - _log: 127.0.0.1 - - [03/Nov/2020 22:44:41] "[37mGET /respuestas HTTP/1.0[0m" 200 -
2020-11-03 22:45:42.686 INFO _internal - _log: 127.0.0.1 - - [03/Nov/2020 22:45:42] "[37mGET /respuestas HTTP/1.0[0m" 200 -
2020-11-03 22:47:56.860 INFO _internal - _log: 127.0.0.1 - - [03/Nov/2020 22:47:56] "[37mGET /respuestas HTTP/1.0[0m" 200 -
2020-11-03 22:49:36.180 INFO _internal - _log: 127.0.0.1 - - [03/Nov/2020 22:49:36] "[37mGET /respuestas HTTP/1.0[0m" 200 -
2020-11-03 22:49:54.601 INFO _internal - _log: 127.0.0.1 - - [03/Nov/2020 22:49:54] "[37mGET /respuestas HTTP/1.0[0m" 200 -
2020-11-03 22:50:14.181 INFO _internal - _log: 127.0.0.1 - - [03/Nov/2020 22:50:14] "[37mGET /respuestas HTTP/1.0[0m" 200 -
2020-11-03 22:51:14.574 INFO _internal - _log: 127.0.0.1 - - [03/Nov/2020 22:51:14] "[37mGET /respuestas HTTP/1.0[0m" 200 -
2020-11-03 22:51:26.275 INFO _internal - _log: 127.0.0.1 - - [03/Nov/2020 22:51:26] "[37mGET /respuestas HTTP/1.0[0m" 200 -
2020-11-03 22:51:36.173 INFO _internal - _log: 127.0.0.1 - - [03/Nov/2020 22:51:36] "[37mGET /respuestas HTTP/1.0[0m" 200 -
2020-11-03 22:51:49.171 INFO api - login: login exitoso
2020-11-03 22:51:49.173 INFO _internal - _log: 127.0.0.1 - - [03/Nov/2020 22:51:49] "[37mPOST /login HTTP/1.0[0m" 200 -
2020-11-03 22:52:51.163 INFO _internal - _log: 127.0.0.1 - - [03/Nov/2020 22:52:51] "[37mGET /respuestas HTTP/1.0[0m" 200 -
2020-11-03 23:00:11.158 INFO api - login: login exitoso
2020-11-03 23:00:11.159 INFO _internal - _log: 127.0.0.1 - - [03/Nov/2020 23:00:11] "[37mPOST /login HTTP/1.0[0m" 200 -
2020-11-03 23:00:28.990 INFO _internal - _log: 127.0.0.1 - - [03/Nov/2020 23:00:28] "[37mGET /respuestas HTTP/1.0[0m" 200 -
2020-11-03 23:00:51.220 INFO api - login: login exitoso
2020-11-03 23:00:51.222 INFO _internal - _log: 127.0.0.1 - - [03/Nov/2020 23:00:51] "[37mPOST /login HTTP/1.0[0m" 200 -
2020-11-03 23:00:56.264 INFO _internal - _log: 127.0.0.1 - - [03/Nov/2020 23:00:56] "[37mGET /respuestas HTTP/1.0[0m" 200 -
2020-11-03 23:02:56.502 INFO _internal - _log: 127.0.0.1 - - [03/Nov/2020 23:02:56] "[37mPOST /responder HTTP/1.1[0m" 200 -
2020-11-03 23:04:17.483 INFO _internal - _log: 127.0.0.1 - - [03/Nov/2020 23:04:17] "[31m[1mPOST /login HTTP/1.1[0m" 400 -
2020-11-03 23:10:42.511 INFO _internal - _log:  * Running on http://0.0.0.0:5000/ (Press CTRL+C to quit)
2020-11-03 23:10:46.504 ERROR app - log_exception: Exception on /responder [POST]
Traceback (most recent call last):
  File "C:\Python\lib\site-packages\flask\app.py", line 2446, in wsgi_app
    response = self.full_dispatch_request()
  File "C:\Python\lib\site-packages\flask\app.py", line 1951, in full_dispatch_request
    rv = self.handle_user_exception(e)
  File "C:\Python\lib\site-packages\flask\app.py", line 1820, in handle_user_exception
    reraise(exc_type, exc_value, tb)
  File "C:\Python\lib\site-packages\flask\_compat.py", line 39, in reraise
    raise value
  File "C:\Python\lib\site-packages\flask\app.py", line 1949, in full_dispatch_request
    rv = self.dispatch_request()
  File "C:\Python\lib\site-packages\flask\app.py", line 1935, in dispatch_request
    return self.view_functions[rule.endpoint](**req.view_args)
  File "api.py", line 76, in responder
    if('username' not in body or 'resp1' not in body or 'resp2' not in body or 'resp3' not in body):
NameError: name 'body' is not defined
2020-11-03 23:10:46.564 INFO _internal - _log: 127.0.0.1 - - [03/Nov/2020 23:10:46] "[35m[1mPOST /responder HTTP/1.1[0m" 500 -
2020-11-03 23:11:18.531 INFO _internal - _log:  * Running on http://0.0.0.0:5000/ (Press CTRL+C to quit)
2020-11-03 23:11:21.578 ERROR app - log_exception: Exception on /responder [POST]
Traceback (most recent call last):
  File "C:\Python\lib\site-packages\flask\app.py", line 2446, in wsgi_app
    response = self.full_dispatch_request()
  File "C:\Python\lib\site-packages\flask\app.py", line 1951, in full_dispatch_request
    rv = self.handle_user_exception(e)
  File "C:\Python\lib\site-packages\flask\app.py", line 1820, in handle_user_exception
    reraise(exc_type, exc_value, tb)
  File "C:\Python\lib\site-packages\flask\_compat.py", line 39, in reraise
    raise value
  File "C:\Python\lib\site-packages\flask\app.py", line 1949, in full_dispatch_request
    rv = self.dispatch_request()
  File "C:\Python\lib\site-packages\flask\app.py", line 1935, in dispatch_request
    return self.view_functions[rule.endpoint](**req.view_args)
  File "api.py", line 100, in responder
    return jsonify({"status","success"}),200
  File "C:\Python\lib\site-packages\flask\json\__init__.py", line 370, in jsonify
    dumps(data, indent=indent, separators=separators) + "\n",
  File "C:\Python\lib\site-packages\flask\json\__init__.py", line 211, in dumps
    rv = _json.dumps(obj, **kwargs)
  File "C:\Python\lib\json\__init__.py", line 234, in dumps
    return cls(
  File "C:\Python\lib\json\encoder.py", line 199, in encode
    chunks = self.iterencode(o, _one_shot=True)
  File "C:\Python\lib\json\encoder.py", line 257, in iterencode
    return _iterencode(o, 0)
  File "C:\Python\lib\site-packages\flask\json\__init__.py", line 100, in default
    return _json.JSONEncoder.default(self, o)
  File "C:\Python\lib\json\encoder.py", line 179, in default
    raise TypeError(f'Object of type {o.__class__.__name__} '
TypeError: Object of type set is not JSON serializable
2020-11-03 23:11:21.627 INFO _internal - _log: 127.0.0.1 - - [03/Nov/2020 23:11:21] "[35m[1mPOST /responder HTTP/1.1[0m" 500 -
2020-11-03 23:11:50.726 INFO _internal - _log:  * Running on http://0.0.0.0:5000/ (Press CTRL+C to quit)
2020-11-03 23:11:53.489 INFO _internal - _log: 127.0.0.1 - - [03/Nov/2020 23:11:53] "[37mPOST /responder HTTP/1.1[0m" 200 -
2020-11-03 23:11:56.137 INFO _internal - _log: 127.0.0.1 - - [03/Nov/2020 23:11:56] "[37mPOST /responder HTTP/1.1[0m" 200 -
2020-11-03 23:11:57.557 INFO _internal - _log: 127.0.0.1 - - [03/Nov/2020 23:11:57] "[37mPOST /responder HTTP/1.1[0m" 200 -
2020-11-03 23:11:58.912 INFO _internal - _log: 127.0.0.1 - - [03/Nov/2020 23:11:58] "[37mPOST /responder HTTP/1.1[0m" 200 -
2020-11-03 23:12:02.276 INFO _internal - _log: 127.0.0.1 - - [03/Nov/2020 23:12:02] "[37mGET /respuestas HTTP/1.1[0m" 200 -
2020-11-03 23:12:26.869 INFO _internal - _log:  * Running on http://0.0.0.0:5000/ (Press CTRL+C to quit)
2020-11-03 23:12:30.399 INFO _internal - _log: 127.0.0.1 - - [03/Nov/2020 23:12:30] "[37mGET /respuestas HTTP/1.1[0m" 200 -
2020-11-03 23:12:44.850 INFO _internal - _log: 127.0.0.1 - - [03/Nov/2020 23:12:44] "[37mPOST /responder HTTP/1.1[0m" 200 -
2020-11-03 23:12:46.673 INFO _internal - _log: 127.0.0.1 - - [03/Nov/2020 23:12:46] "[37mPOST /responder HTTP/1.1[0m" 200 -
2020-11-03 23:13:13.117 INFO _internal - _log:  * Running on http://0.0.0.0:5000/ (Press CTRL+C to quit)
2020-11-03 23:13:16.211 INFO _internal - _log: 127.0.0.1 - - [03/Nov/2020 23:13:16] "[37mPOST /responder HTTP/1.1[0m" 200 -
2020-11-03 23:13:17.463 INFO _internal - _log: 127.0.0.1 - - [03/Nov/2020 23:13:17] "[31m[1mPOST /responder HTTP/1.1[0m" 400 -
2020-11-03 23:13:19.157 INFO _internal - _log: 127.0.0.1 - - [03/Nov/2020 23:13:19] "[31m[1mPOST /responder HTTP/1.1[0m" 400 -
2020-11-03 23:13:21.710 INFO _internal - _log: 127.0.0.1 - - [03/Nov/2020 23:13:21] "[37mGET /respuestas HTTP/1.1[0m" 200 -
2020-11-03 23:13:26.021 INFO _internal - _log: 127.0.0.1 - - [03/Nov/2020 23:13:26] "[37mGET /respuestas HTTP/1.1[0m" 200 -
2020-11-03 23:13:27.534 INFO _internal - _log: 127.0.0.1 - - [03/Nov/2020 23:13:27] "[31m[1mPOST /responder HTTP/1.1[0m" 400 -
2020-11-03 23:14:28.610 INFO _internal - _log:  * Running on http://0.0.0.0:5000/ (Press CTRL+C to quit)
2020-11-03 23:14:31.373 INFO _internal - _log: 127.0.0.1 - - [03/Nov/2020 23:14:31] "[37mPOST /responder HTTP/1.1[0m" 200 -
2020-11-03 23:14:34.499 INFO _internal - _log: 127.0.0.1 - - [03/Nov/2020 23:14:34] "[37mPOST /responder HTTP/1.1[0m" 200 -
2020-11-03 23:14:38.828 INFO _internal - _log: 127.0.0.1 - - [03/Nov/2020 23:14:38] "[37mPOST /responder HTTP/1.1[0m" 200 -
2020-11-03 23:14:40.257 INFO _internal - _log: 127.0.0.1 - - [03/Nov/2020 23:14:40] "[37mPOST /responder HTTP/1.1[0m" 200 -
2020-11-03 23:17:00.796 INFO _internal - _log:  * Running on http://0.0.0.0:5000/ (Press CTRL+C to quit)
2020-11-03 23:17:09.155 ERROR app - log_exception: Exception on /responder [POST]
Traceback (most recent call last):
  File "C:\Python\lib\site-packages\flask\app.py", line 2446, in wsgi_app
    response = self.full_dispatch_request()
  File "C:\Python\lib\site-packages\flask\app.py", line 1951, in full_dispatch_request
    rv = self.handle_user_exception(e)
  File "C:\Python\lib\site-packages\flask\app.py", line 1820, in handle_user_exception
    reraise(exc_type, exc_value, tb)
  File "C:\Python\lib\site-packages\flask\_compat.py", line 39, in reraise
    raise value
  File "C:\Python\lib\site-packages\flask\app.py", line 1949, in full_dispatch_request
    rv = self.dispatch_request()
  File "C:\Python\lib\site-packages\flask\app.py", line 1935, in dispatch_request
    return self.view_functions[rule.endpoint](**req.view_args)
  File "api.py", line 88, in responder
    cursor.execute(query,month,body.username)
AttributeError: 'dict' object has no attribute 'username'
2020-11-03 23:17:09.159 INFO _internal - _log: 127.0.0.1 - - [03/Nov/2020 23:17:09] "[35m[1mPOST /responder HTTP/1.1[0m" 500 -
2020-11-03 23:17:48.367 INFO _internal - _log:  * Running on http://0.0.0.0:5000/ (Press CTRL+C to quit)
2020-11-03 23:17:52.915 ERROR app - log_exception: Exception on /responder [POST]
Traceback (most recent call last):
  File "C:\Python\lib\site-packages\flask\app.py", line 2446, in wsgi_app
    response = self.full_dispatch_request()
  File "C:\Python\lib\site-packages\flask\app.py", line 1951, in full_dispatch_request
    rv = self.handle_user_exception(e)
  File "C:\Python\lib\site-packages\flask\app.py", line 1820, in handle_user_exception
    reraise(exc_type, exc_value, tb)
  File "C:\Python\lib\site-packages\flask\_compat.py", line 39, in reraise
    raise value
  File "C:\Python\lib\site-packages\flask\app.py", line 1949, in full_dispatch_request
    rv = self.dispatch_request()
  File "C:\Python\lib\site-packages\flask\app.py", line 1935, in dispatch_request
    return self.view_functions[rule.endpoint](**req.view_args)
  File "api.py", line 88, in responder
    cursor.execute(query,month,body.username)
AttributeError: 'dict' object has no attribute 'username'
2020-11-03 23:17:52.917 INFO _internal - _log: 127.0.0.1 - - [03/Nov/2020 23:17:52] "[35m[1mPOST /responder HTTP/1.1[0m" 500 -
2020-11-03 23:18:34.966 INFO _internal - _log:  * Running on http://0.0.0.0:5000/ (Press CTRL+C to quit)
2020-11-03 23:18:37.347 ERROR app - log_exception: Exception on /responder [POST]
Traceback (most recent call last):
  File "C:\Python\lib\site-packages\flask\app.py", line 2446, in wsgi_app
    response = self.full_dispatch_request()
  File "C:\Python\lib\site-packages\flask\app.py", line 1951, in full_dispatch_request
    rv = self.handle_user_exception(e)
  File "C:\Python\lib\site-packages\flask\app.py", line 1820, in handle_user_exception
    reraise(exc_type, exc_value, tb)
  File "C:\Python\lib\site-packages\flask\_compat.py", line 39, in reraise
    raise value
  File "C:\Python\lib\site-packages\flask\app.py", line 1949, in full_dispatch_request
    rv = self.dispatch_request()
  File "C:\Python\lib\site-packages\flask\app.py", line 1935, in dispatch_request
    return self.view_functions[rule.endpoint](**req.view_args)
  File "api.py", line 88, in responder
    cursor.execute(query,month,body.username)
AttributeError: 'dict' object has no attribute 'username'
2020-11-03 23:18:37.350 INFO _internal - _log: 127.0.0.1 - - [03/Nov/2020 23:18:37] "[35m[1mPOST /responder HTTP/1.1[0m" 500 -
2020-11-03 23:19:01.658 INFO _internal - _log:  * Running on http://0.0.0.0:5000/ (Press CTRL+C to quit)
2020-11-03 23:19:04.655 INFO _internal - _log: 127.0.0.1 - - [03/Nov/2020 23:19:04] "[37mPOST /responder HTTP/1.1[0m" 200 -
2020-11-03 23:19:07.660 INFO _internal - _log: 127.0.0.1 - - [03/Nov/2020 23:19:07] "[37mPOST /responder HTTP/1.1[0m" 200 -
2020-11-03 23:19:08.895 INFO _internal - _log: 127.0.0.1 - - [03/Nov/2020 23:19:08] "[37mPOST /responder HTTP/1.1[0m" 200 -
2020-11-03 23:19:10.017 INFO _internal - _log: 127.0.0.1 - - [03/Nov/2020 23:19:10] "[37mPOST /responder HTTP/1.1[0m" 200 -
2020-11-03 23:19:11.121 INFO _internal - _log: 127.0.0.1 - - [03/Nov/2020 23:19:11] "[37mPOST /responder HTTP/1.1[0m" 200 -
2020-11-03 23:20:06.842 INFO _internal - _log:  * Running on http://0.0.0.0:5000/ (Press CTRL+C to quit)
2020-11-03 23:20:10.772 INFO _internal - _log: 127.0.0.1 - - [03/Nov/2020 23:20:10] "[37mPOST /responder HTTP/1.1[0m" 200 -
2020-11-03 23:20:11.907 INFO _internal - _log: 127.0.0.1 - - [03/Nov/2020 23:20:11] "[37mPOST /responder HTTP/1.1[0m" 200 -
2020-11-03 23:20:13.349 INFO _internal - _log: 127.0.0.1 - - [03/Nov/2020 23:20:13] "[37mPOST /responder HTTP/1.1[0m" 200 -
2020-11-03 23:26:17.821 INFO _internal - _log:  * Running on http://0.0.0.0:5000/ (Press CTRL+C to quit)
2020-11-03 23:27:10.776 INFO _internal - _log: 127.0.0.1 - - [03/Nov/2020 23:27:10] "[37mPOST /responder HTTP/1.0[0m" 200 -
2020-11-03 23:27:17.094 INFO _internal - _log: 127.0.0.1 - - [03/Nov/2020 23:27:17] "[37mGET /respuestas HTTP/1.0[0m" 200 -
